Workbook
Name Slicer_month: #N/A
Name Slicer_month1: #N/A
Name Slicer_year: #N/A
Name Slicer_year1: #N/A

Sheet Sheet4
A3: Sum of Sales | B3: Sum of Profit | C3: Sum of Quantity
A4: 589650.1 | B4: 129071.84 | C4: 5758
G17: Row Labels | H17: Sum of Sales
G18: 2021 | H18: 14343.21
G19: Grand Total | H19: 14343.21

Sheet Dataset
A1: Row ID | B1: Order ID | C1: Ship Mode | D1: Customer ID | E1: Customer Name | F1: Segment | G1: City | H1: State | I1: Country | J1: Region | K1: Product ID | L1: Category | M1: Sub-Category | N1: Product Name | O1: Sales | P1: Quantity | Q1: Profit | R1: Shipping Cost | S1: Order Priority | T1: Target | U1: Manager | V1: Team lead | W1: Gender | X1: Order Date | Y1: month | Z1: year | AA1: Ship Date
A2: 1 | B2: IN-2014-54694 | C2: Standard Class | D2: HG-14845 | E2: Harry Greene | F2: Consumer | G2: Rajkot | H2: Gujarat | I2: India | J2: West | K2: OFF-BI-10001312 | L2: Office Supplies | M2: Binders | N2: Cardinal 3-Hole Punch, Clear | O2: 56.52 | P2: 2 | Q2: 23.7 | R2: 2.15 | S2: Medium | T2: 386 | U2: Mahesh | V2: Mohit | W2: Male | X2: 45303 | Y2: =TEXT(X2,"mmmm") -> January | Z2: =YEAR(X2) -> 2024 | AA2: 45424
A3: 2 | B3: IN-2013-53763 | C3: Standard Class | D3: AR-10510 | E3: Andrew Roberts | F3: Consumer | G3: Durg | H3: Chhattisgarh | I3: India | J3: East | K3: OFF-BI-10002386 | L3: Office Supplies | M3: Binders | N3: Acco Index Tab, Clear | O3: 1000 | P3: 2 | Q3: 2.04 | R3: 1.5 | S3: Medium | T3: 401 | U3: Mahesh | V3: Mohan | W3: Female | X3: 45287 | Y3: =TEXT(X3,"mmmm") -> December | Z3: =YEAR(X3) -> 2023 | AA3: 45291
A4: 3 | B4: IN-2014-15473 | C4: Standard Class | D4: TP-21130 | E4: Theone Pippenger | F4: Consumer | G4: Mangalore | H4: Karnataka | I4: India | J4: South | K4: OFF-BI-10004436 | L4: Office Supplies | M4: Binders | N4: Acco Hole Reinforcements, Recycled | O4: 14.04 | P4: 2 | Q4: 0.24 | R4: 0.79 | S4: Medium | T4: 293 | U4: Mahesh | V4: Manu | W4: Female | X4: 45334 | Y4: =TEXT(X4,"mmmm") -> February | Z4: =YEAR(X4) -> 2024 | AA4: 45485
A5: 4 | B5: IN-2014-24622 | C5: Standard Class | D5: MM-17920 | E5: Michael Moore | F5: Consumer | G5: Bijapur | H5: Karnataka | I5: India | J5: South | K5: OFF-BI-10002885 | L5: Office Supplies | M5: Binders | N5: Avery Hole Reinforcements, Recycled | O5: 9.54 | P5: 2 | Q5: 4.44 | R5: 0.14 | S5: Medium | T5: 609 | U5: Mahesh | V5: Meena | W5: Female | X5: 45587 | Y5: =TEXT(X5,"mmmm") -> October | Z5: =YEAR(X5) -> 2024 | AA5: 45593
A6: 5 | B6: IN-2012-29130 | C6: Standard Class | D6: JR-15700 | E6: Jocasta Rupert | F6: Consumer | G6: Kollam | H6: Kerala | I6: India | J6: South | K6: OFF-ST-10001290 | L6: Office Supplies | M6: Storage | N6: Rogers Shelving, Single Width | O6: 124.32 | P6: 2 | Q6: 54.66 | R6: 11.12 | S6: Medium | T6: 750 | U6: Mahesh | V6: Mohan | W6: Male | X6: 44466 | Y6: =TEXT(X6,"mmmm") -> September | Z6: =YEAR(X6) -> 2021 | AA6: 44206
A7: 6 | B7: IN-2013-22648 | C7: Standard Class | D7: SF-20065 | E7: Sandra Flanagan | F7: Consumer | G7: Ratlam | H7: Madhya Pradesh | I7: India | J7: West | K7: OFF-ST-10000327 | L7: Office Supplies | M7: Storage | N7: Smead Folders, Wire Frame | O7: 33.12 | P7: 2 | Q7: 4.62 | R7: 0.91 | S7: Medium | T7: 647 | U7: Mahesh | V7: Manu | W7: Female | X7: 44728 | Y7: =TEXT(X7,"mmmm") -> June | Z7: =YEAR(X7) -> 2022 | AA7: 44734
A8: 7 | B8: IN-2011-24769 | C8: Standard Class | D8: JM-15535 | E8: Jessica Myrick | F8: Consumer | G8: Solapur | H8: Maharashtra | I8: India | J8: West | K8: OFF-EN-10003632 | L8: Office Supplies | M8: Envelopes | N8: Jiffy Mailers, Recycled | O8: 71.94 | P8: 2 | Q8: 10.74 | R8: 8.46 | S8: Medium | T8: 167 | U8: Mahesh | V8: Meena | W8: Female | X8: 45060 | Y8: =TEXT(X8,"mmmm") -> May | Z8: =YEAR(X8) -> 2023 | AA8: 45066
A9: 8 | B9: IN-2012-43165 | C9: Standard Class | D9: MM-17260 | E9: Magdelene Morse | F9: Consumer | G9: Puducherry | H9: Puducherry | I9: India | J9: South | K9: OFF-EN-10002007 | L9: Office Supplies | M9: Envelopes | N9: Kraft Clasp Envelope, with clear poly window | O9: 25.08 | P9: 2 | Q9: 3.96 | R9: 1.88 | S9: Medium | T9: 189 | U9: Mahesh | V9: Mohit | W9: Female | X9: 44325 | Y9: =TEXT(X9,"mmmm") -> May | Z9: =YEAR(X9) -> 2021 | AA9: 44509
A10: 9 | B10: IN-2012-32882 | C10: Standard Class | D10: TR-21325 | E10: Toby Ritter | F10: Consumer | G10: Kanpur | H10: Uttar Pradesh | I10: India | J10: North | K10: OFF-LA-10003273 | L10: Office Supplies | M10: Labels | N10: Harbour Creations Color Coded Labels, Adjustable | O10: 21.6 | P10: 2 | Q10: 1.26 | R10: 1.38 | S10: Medium | T10: 774 | U10: Mahesh | V10: Mohan | W10: Male | X10: 44585 | Y10: =TEXT(X10,"mmmm") -> January | Z10: =YEAR(X10) -> 2022 | AA10: 44591
A11: 10 | B11: IN-2011-59510 | C11: Standard Class | D11: DK-12985 | E11: Darren Koutras | F11: Consumer | G11: Meerut | H11: Uttar Pradesh | I11: India | J11: North | K11: OFF-LA-10002272 | L11: Office Supplies | M11: Labels | N11: Smead File Folder Labels, Alphabetical | O11: 17.4 | P11: 2 | Q11: 1.38 | R11: 1.36 | S11: Medium | T11: 389 | U11: Mahesh | V11: Manu | W11: Female | X11: 44790 | Y11: =TEXT(X11,"mmmm") -> August | Z11: =YEAR(X11) -> 2022 | AA11: 44795
A12: 11 | B12: IN-2014-63766 | C12: Standard Class | D12: MK-18160 | E12: Mike Kennedy | F12: Consumer | G12: Mangalore | H12: Karnataka | I12: India | J12: South | K12: OFF-LA-10004745 | L12: Office Supplies | M12: Labels | N12: Harbour Creations Shipping Labels, Adjustable | O12: 18.72 | P12: 2 | Q12: 9.12 | R12: 1.26 | S12: Medium | T12: 585 | U12: Mahesh | V12: Meena | W12: Male | X12: 44273 | Y12: =TEXT(X12,"mmmm") -> March | Z12: =YEAR(X12) -> 2021 | AA12: 44278
A13: 12 | B13: IN-2011-78823 | C13: Standard Class | D13: ME-17725 | E13: Max Engle | F13: Consumer | G13: Raipur | H13: Rajasthan | I13: India | J13: West | K13: OFF-FA-10000577 | L13: Office Supplies | M13: Fasteners | N13: Stockwell Push Pins, 12 Pack | O13: 26.82 | P13: 2 | Q13: 13.38 | R13: 2.49 | S13: Medium | T13: 146 | U13: Mahesh | V13: Mohit | W13: Male | X13: 45618 | Y13: =TEXT(X13,"mmmm") -> November | Z13: =YEAR(X13) -> 2024 | AA13: 45622
... A1556: 1555 | B1556: IN-2013-14675 | C1556: Standard Class | D1556: CS-12130 | E1556: Chad Sievert | F1556: Consumer | G1556: Bilaspur | H1556: Uttar Pradesh | I1556: India | J1556: North | K1556: TEC-CO-10002035 | L1556: Technology | M1556: Copiers | N1556: Canon Wireless Fax, High-Speed | O1556: 753.72 | P1556: 2 | Q1556: 60.24 | R1556: 74.65 | S1556: Medium | T1556: 542 | U1556: Suresh | V1556: Sunil | W1556: Female | X1556: 44587 | Y1556: =TEXT(X1556,"mmmm") -> January | Z1556: =YEAR(X1556) -> 2022 | AA1556: 44591

Sheet Questions
A1: Sales, Profit, and Quantity Analysis
A3: 1. What is the total Sales, Profit, and Quantity sold across all records?
A5: 2. Which Product Name has the highest Sales?
A7: 3. Which Customer placed the highest number of orders? | G7: Customer_name wise count of orders
A9: 4. What is the average Sales and Profit per order? | G9: order wise avg sales and avg profit
A11: 5. Which Region has the highest total profit? | G11: Region wise sum of profit
A15: 2. Date & Time Based Questions
A17: 6. How many orders were placed in each year?
A19: 7. Calculate the number of days taken to ship each order (Ship Date - Order Date). What is the average shipping time?
A21: 8. Identify orders where shipping took more than 10 days.
A23: 9. Count how many orders were placed in each month.
A25: 10. Which month had the highest Sales?
A29: 3. Location-Based Questions
A31: 11. What are the total Sales and Profit by State?
A33: 12. Which City contributed the most to overall profit?
A35: 13. Group Sales by Region and compare average Shipping Cost per region.
A37: 14. Which states have negative profit?
A41: 4. Product/Category Questions
... A159: 25. Show Sub-Categories that contributed over ₹1000 in total Profit.

Sheet DASHBOARD1

Sheet Sheet1

Sheet DASHBOARD2

Sheet solution
A7: Ans 1
A9: KPI's
A10: Total Sales | B10: Total Profit | C10: Total Quantity Ordered
A11: =SUM(Dataset!O2:O1556) -> 590632.94 | B11: =SUM(Dataset!Q2:Q1556) -> 129071.84 | C11: =SUM(Dataset!P2:P1556) -> 5758
A13: TotalSales | B13: TotalProfit | C13: TotalQuantityOrdered
A14: 589650.1 | B14: 129071.84 | C14: 5758
A17: Total Sales | B17: Total Profit | C17: Total Quantity Ordered | D17: Total Orders | E17: Total Customers
A18: 589650.1 | B18: 129071.84 | C18: 5758 | D18: =COUNTA(Dataset!B2:B1556) -> 1555 | E18: =COUNTA(_xlfn.UNIQUE(Dataset!E2:E1556)) -> 494
A23: Ans2
A26: Product Name | B26: Sum of Sales
A27: Motorola Smart Phone, with Caller ID | B27: 9683.1
A28: Sauder Classic Bookcase, Traditional | B28: 7847.82
A29: Apple Smart Phone, Full Size | B29: 7650
A30: Cisco Smart Phone, Full Size | B30: 5870.25
A31: Bush Library with Doors, Metal | B31: 5820.48
A32: Grand Total | B32: 36871.65
A40: Ans3
A41: Customer_Name | B41: Count of Order ID
A42: Arthur Gainer | B42: 17
A43: Katherine Ducich | B43: 12
A44: Luke Foster | B44: 11
A45: Lena Radford | B45: 10
A46: Lisa DeCherney | B46: 10
A47: Harry Greene | B47: 10
A48: Jessica Myrick | B48: 10
A49: Richard Bierner | B49: 9
A50: Corey-Lock | B50: 9
A51: Stewart Carmichael | B51: 9
A52: Alejandro Savely | B52: 9
A53: Frank Gastineau | B53: 9
A54: Grand Total | B54: 125
A57: Ans4
A60: Order Id | B60: Average of Sales | C60: Average of Profit
A61: IN-2012-26274 | B61: 2761.29 | C61: 180.99
A62: IN-2012-29571 | B62: 3187.5 | C62: 350.55
A63: IN-2012-79439 | B63: 3076.5 | C63: 215.25
A64: IN-2013-46798 | B64: 3180.3 | C64: 381.6
A65: IN-2013-50809 | B65: 5751.54 | C65: 2817.99
A66: Grand Total | B66: 3453.07 | C66: 687.895
A75: Row Labels | B75: Sum of Sales
...

Sheet KPI
A1: KPI | B1: Key Performance Indecator is a measurable value that shows how well a business ,team or process is achieving its goals
B2: It tells you whether performance is improving , declining or staying the same
B3: e.g Total Sales
B4: Total Customers
B5: Total Orders
B6: Revenue growth %
B7: Total Profit

Sheet Charts or graphs
A2: 1 | B2: Column chart | C2: when we use columnor bar chart
B3: vertical bars | C3: e.g.1. region wise total sales
A4: 2 | B4: bar chart | C4: 2. year wise total profit
B5: Horizontal bars | C5: 3.categorywise total qty ordered
B7: Column chart(vertical) | C7: Text | D7: Numeric
C8: X-axis | D8: Y-axis
B9: Bar chart(Horizontal) | C9: Text | D9: Numeric
C10: Y-axis | D10: X-axis
N11: Year | O11: Sum of Sales
A12: 3 | B12: Pie chart | C12: when we want to display % contribution | N12: 2022 | O12: 10683.24
N13: Grand Total | O13: 10683.24
A14: 4 | B14: Donught chart | C14: when we want to display % contribution
C15: e.g. calculate year wise % of total sales
A18: DASHBOARD | B18: It is a visual display of important information,shown in a single screen using charts,numbers,tables ,slicers(filter) and KPIs
B19: it is used to monitor performance,track trends and make decisions | O19: =O15/O16 -> #DIV/0!
A21: 6 | B21: Tree map/Hierarchy chart | C21: Top5
A23: 7 | B23: Funnel chart | C23: Top/Bottom
A25: 8 | B25: map chart | C25: Location/City/Region
A27: 9 | B27: scatter chart | C27: To show relation between two numeric columns
C28: e.g. sales vs profit
C31: Car age | D31: Car price
C32: 1 | D32: 5000
C33: 2 | D33: 4000
C34: 3 | D34: 3500
C35: 4 | D35: 3000
C36: 5 | D36: 2500
C37: 6 | D37: 2000
C38: 7 | D38: 1000
C39: 8 | D39: 900
C41: Height | D41: weight
C42: 130 | D42: 30
C43: 140 | D43: 40
C44: 145 | D44: 50
C45: 150 | D45: 60
C46: 155 | D46: 70
C47: 156 | D47: 80
A49: 10 | B49: line chart | C49: Time sereies data
C50: to show trends
A53: 11 | B53: Histogram | C53: Single column numeric
C54: To show frequency dustribution
...
